Workbook

Sheet Dashboard
A1: Multi-Channel Inventory & Sales Analytics Dashboard
A3: Interactive analysis of inventory and sales across Flipkart, Amazon & Myntra
A5: Total Sales | D5: Total Inventory | G5: Acer Stock | J5: Active Marketplaces
A6: =SUM(tblSuitcaseSeries[Total Sales Out]) -> 146 | D6: =SUM(tblSuitcaseSeries[Total Inventory]) -> 4328 | G6: =SUM(tblSuitcaseSeries[Acer Stock]) -> 2945 | J6: 3 Active
A9: Best Selling Series | D9: Highest Inventory | G9: Total Inventory Value | J9: Highest Value Series
A10: ='Pivot Tables'!A4&" - "&'Pivot Tables'!B4&" units" -> Cassian - 53 units | D10: ='Pivot Tables'!A17&" - "&'Pivot Tables'!B17&" units" -> Romulus - 1700 units | G10: ='Pivot Tables'!H10 -> 81608672 | J10: ='Pivot Tables'!G4&" - ₹ "&TEXT('Pivot Tables'!H4,"#,##,##0") -> Romulus - ₹ 3,29,06,300
A13: Sales by Series | H13: Marketplace Sales | O13: Flipkart Sales Trend Jun - July
A33: Inventory by Series | H33: Marketplace Stock
A53: Inventory Value By Series | H53: Inventory Value By Location
A71: Business Insights
A73: • Sales Performance: Cassian is the best-selling series with 53 units sold, followed by Romulus with 41 units. Together, they account for 64% of total sales.
A74: • Inventory Status: Romulus has the highest inventory at 1,700 units, followed by Cassian at 1,380 units. Orion has the lowest inventory at 52 units.
A75: • Marketplace Performance: Flipkart contributes 71% of total sales (104 units) and holds 71% of marketplace stock (987 units), making it the dominant marketplace.
A76: • Stock Risk: Orion has the lowest inventory at 52 units while recording the highest sell-through among the series at approximately 42%. Myntra holds only 18 units (1.3% of marketplace stock) despite contributing 8% of total sales. units (1.5% of marketplace stock) despite contributing 10% of total sales.
A77: • Recommendation: Prioritize replenishing Orion inventory due to its high sell-through rate. Review slower-moving inventory such as Evander and Aurelia, which have substantially higher stock relative to sales, to optimize inventory allocation.

Sheet Product Master
A1: Series | B1: Product Name | C1: Part Number | D1: FSN | E1: ASIN | F1: Myntra SKU Code | G1: MRP | H1: Size | I1: Colour | J1: Material | K1: Opening Type | L1: Expandable | M1: Notes
A2: Orion | B2: Acer Orion Suitcase 20 inch Cabin with 360 degree spin 8 Wheels TSA lock Mid-Open Polycarbonate Black | C2: PN - 001 | D2: FSIN - 001 | G2: 13999 | H2: Cabin | I2: Black | J2: Polycarbonate | K2: Mid-Open | L2: No
A3: Orion | B3: Acer Orion Suitcase 20 inch Cabin with 360 degree spin 8 Wheels TSA lock Mid-Open Polycarbonate White | C3: PN - 002 | D3: FSIN - 002 | G3: 13999 | H3: Cabin | I3: White | J3: Polycarbonate | K3: Mid-Open | L3: No
A4: Orion | B4: Acer Orion Suitcase 24 inch Check-in with 360 degree spin 8 Wheels TSA lock Mid-Open Polycarbonate Black | C4: PN - 003 | D4: FSIN - 003 | G4: 16999 | H4: Check-in | I4: Black | J4: Polycarbonate | K4: Mid-Open | L4: No
A5: Orion | B5: Acer Orion Suitcase 24 inch Check-in with 360 degree spin 8 Wheels TSA lock Mid-Open Polycarbonate White | C5: PN - 004 | D5: FSIN - 004 | G5: 16999 | H5: Check-in | I5: White | J5: Polycarbonate | K5: Mid-Open | L5: No
A6: Aurelia | B6: Acer Aurelia Suitcase 19.5 inch Carry-on with 360 degree spin 8 Wheels TSA lock Mid-Open Expandable rPET Black | C6: PN - 005 | D6: FSIN - 005 | G6: 10999 | H6: Carry-on | I6: Black | J6: rPET | K6: Mid-Open | L6: Yes
A7: Aurelia | B7: Acer Aurelia Suitcase 19.5 inch Carry-on with 360 degree spin 8 Wheels TSA lock Mid-Open Expandable rPET White | C7: PN - 006 | D7: FSIN - 006 | G7: 10999 | H7: Carry-on | I7: White | J7: rPET | K7: Mid-Open | L7: Yes
A8: Aurelia | B8: Acer Aurelia Suitcase 24 inch Check-in with 360 degree spin 8 Wheels TSA lock Mid-Open Expandable rPET Black | C8: PN - 007 | D8: FSIN - 007 | E8: ASIN - 001 | F8: SKU - 001 | G8: 12999 | H8: Check-in | I8: Black | J8: rPET | K8: Mid-Open | L8: Yes
A9: Aurelia | B9: Acer Aurelia Suitcase 24 inch Check-in with 360 degree spin 8 Wheels TSA lock Mid-Open Expandable rPET White | C9: PN - 008 | D9: FSIN - 008 | E9: ASIN - 002 | F9: SKU - 002 | G9: 12999 | H9: Check-in | I9: White | J9: rPET | K9: Mid-Open | L9: Yes
A10: Aurelia | B10: Acer Aurelia Suitcase 19.5+24+28 inch Check-in with 360 degree spin 8 Wheels TSA lock Mid-Open Expandable rPET Black (Set of 3) | C10: PN - 009 | D10: FSIN - 009 | G10: 37999 | H10: Set | I10: Black | J10: rPET | K10: Mid-Open | L10: Yes
A11: Aurelia | B11: Acer Aurelia Suitcase 19.5+24+28 inch Check-in with 360 degree spin 8 Wheels TSA lock Mid-Open Expandable rPET White (Set of 3) | C11: PN - 010 | D11: FSIN - 010 | G11: 37999 | H11: Set | I11: White | J11: rPET | K11: Mid-Open | L11: Yes
A12: Cassian | B12: Acer Cassian Suitcase 20 inch Carry-on with 360 degree spin 8 Wheels TSA lock Top Open Expandable rPET Moreton Sand | C12: PN - 011 | D12: FSIN - 011 | E12: ASIN - 003 | F12: SKU - 003 | G12: 15999 | H12: Carry-on | I12: Moreton Sand | J12: rPET | K12: Top-Open | L12: Yes
A13: Cassian | B13: Acer Cassian Suitcase 20 inch Carry-on with 360 degree spin 8 Wheels TSA lock Top Open Expandable rPET Gold Coast | C13: PN - 012 | D13: FSIN - 012 | E13: ASIN - 004 | G13: 15999 | H13: Carry-on | I13: Gold Coast | J13: rPET | K13: Top-Open | L13: Yes
A14: Cassian | B14: Acer Cassian Suitcase 20 inch Carry-on with 360 degree spin 8 Wheels TSA lock Top Open Expandable rPET Jacaranda Pink | C14: PN - 013 | D14: FSIN - 013 | E14: ASIN - 005 | G14: 15999 | H14: Carry-on | I14: Jacaranda Pink | J14: rPET | K14: Top-Open | L14: Yes
A15: Cassian | B15: Acer Cassian Suitcase 24 inch Check-in with 360 degree spin 8 Wheels Double TSA lock Top & Mid-Open Expandable rPET Moreton Sand | C15: PN - 014 | D15: FSIN - 014 | E15: ASIN - 006 | F15: SKU - 004 | G15: 17999 | H15: Check-in | I15: Moreton Sand | J15: rPET | K15: Dual Opening | L15: Yes
A16: Cassian | B16: Acer Cassian Suitcase 24 inch Check-in with 360 degree spin 8 Wheels Double TSA lock Top & Mid-Open Expandable rPET Gold Coast | C16: PN - 015 | D16: FSIN - 015 | E16: ASIN - 007 | G16: 17999 | H16: Check-in | I16: Gold Coast | J16: rPET | K16: Dual Opening | L16: Yes
A17: Cassian | B17: Acer Cassian Suitcase 24 inch Check-in with 360 degree spin 8 Wheels Double TSA lock Top & Mid-Open Expandable rPET Jacaranda Pink | C17: PN - 016 | D17: FSIN - 016 | E17: ASIN - 008 | G17: 17999 | H17: Check-in | I17: Jacaranda Pink | J17: rPET | K17: Dual Opening | L17: Yes
A18: Cassian | B18: Acer Cassian Suitcase 28 inch Check-in with 360 degree spin 8 Wheels Double TSA lock Top & Mid-Open Expandable rPET Moreton Sand | C18: PN - 017 | D18: FSIN - 017 | E18: ASIN - 009 | G18: 20999 | H18: Check-in | I18: Moreton Sand | J18: rPET | K18: Dual Opening | L18: Yes
A19: Cassian | B19: Acer Cassian Suitcase 28 inch Check-in with 360 degree spin 8 Wheels Double TSA lock Top & Mid-Open Expandable rPET Jacaranda Pink | C19: PN - 018 | D19: FSIN - 018 | E19: ASIN - 010 | F19: SKU - 005 | G19: 20999 | H19: Check-in | I19: Jacaranda Pink | J19: rPET | K19: Dual Opening | L19: Yes
A20: Cassian | B20: Acer Cassian Suitcase 28 inch Check-in with 360 degree spin 8 Wheels Double TSA lock Top & Mid-Open Expandable rPET Gold Coast | C20: PN - 019 | D20: TBC | E20: TBC | F20: TBC | G20: 20999 | H20: Check-in | I20: Gold Coast | J20: rPET | K20: Top & Mid-Open | L20: Yes
A21: Romulus | B21: Acer Romulus Overnighter Suitcase 19 inch Cabin with 360 degree spin 8 Wheels Double TSA lock Top-Open with Quick access compartment rPET Black | C21: PN - 020 | D21: FSIN - 019 | E21: ASIN - 011 | F21: SKU - 006 | G21: 25999 | H21: Overnighter | I21: Black | J21: rPET | K21: Top-Open | L21: No
A22: Romulus | B22: Acer Romulus Overnighter Suitcase 19 inch Cabin with 360 degree spin 8 Wheels Double TSA lock Top-Open with Quick access compartment rPET Aqua Blue | C22: PN - 021 | D22: FSIN - 020 | E22: ASIN - 012 | F22: SKU - 007 | G22: 25999 | H22: Overnighter | I22: Aqua Blue | J22: rPET | K22: Top-Open | L22: No
A23: Romulus | B23: Acer Romulus Overnighter Suitcase 19 inch Cabin with 360 degree spin 8 Wheels Double TSA lock Top-Open with Quick access compartment rPET Pink | C23: PN - 022 | D23: FSIN - 021 | E23: ASIN - 013 | G23: 25999 | H23: Overnighter | I23: Pink | J23: rPET | K23: Top-Open | L23: No
A24: Romulus | B24: Acer Romulus Suitcase 20 inch Cabin with 360 degree spin 8 Wheels TSA lock Top-Open Expandable with Quick access compartment PET White | C24: PN - 023 | D24: FSIN - 022 | E24: ASIN - 014 | G24: 15999 | H24: Cabin | I24: White | J24: PET | K24: Top-Open | L24: Yes
A25: Romulus | B25: Acer Romulus Suitcase 20 inch Cabin with 360 degree spin 8 Wheels TSA lock Top-Open Expandable with Quick access compartment PET Aqua Blue | C25: PN - 024 | D25: FSIN - 023 | G25: 15999 | H25: Cabin | I25: Aqua Blue | J25: PET | K25: Top-Open | L25: Yes
A26: Romulus | B26: Acer Romulus Suitcase 20 inch Cabin with 360 degree spin 8 Wheels TSA lock Top-Open Expandable with Quick access compartment rPET Green | C26: PN - 025 | D26: FSIN - 024 | G26: 15999 | H26: Cabin | I26: Green | J26: rPET | K26: Top-Open | L26: Yes
A27: Romulus | B27: Acer Romulus Suitcase 20 inch Cabin with 360 degree spin 8 Wheels TSA lock Top-Open Expandable with Quick access compartment rPET Pink | C27: PN - 026 | D27: FSIN - 025 | G27: 15999 | H27: Cabin | I27: Pink | J27: rPET | K27: Top-Open | L27: Yes
A28: Romulus | B28: Acer Romulus Suitcase 25 inch Check-in with 360 degree spin 8 Wheels TSA lock Top-Open Expandable rPET Black | C28: PN - 027 | D28: FSIN - 026 | E28: ASIN - 015 | G28: 17999 | H28: Check-in | I28: Black | J28: rPET | K28: Top-Open | L28: Yes
A29: Romulus | B29: Acer Romulus Suitcase 25 inch Check-in with 360 degree spin 8 Wheels TSA lock Top-Open Expandable rPET Green | C29: PN - 028 | D29: FSIN - 027 | G29: 17999 | H29: Check-in | I29: Green | J29: rPET | K29: Top-Open | L29: Yes
A30: Romulus | B30: Acer Romulus Suitcase 25 inch Check-in with 360 degree spin 8 Wheels TSA lock Top-Open Expandable rPET Pink | C30: PN - 029 | D30: FSIN - 028 | E30: ASIN - 016 | G30: 17999 | H30: Check-in | I30: Pink | J30: rPET | K30: Top-Open | L30: Yes
A31: Romulus | B31: Acer Romulus Suitcase 28 inch Check-in with 360 degree spin 8 Wheels TSA lock Top-Open Expandable rPET Black | C31: PN - 030 | D31: FSIN - 029 | G31: 19999 | H31: Check-in | I31: Black | J31: rPET | K31: Top-Open | L31: Yes
A32: Romulus | B32: Acer Romulus Suitcase 28 inch Check-in with 360 degree spin 8 Wheels TSA lock Top-Open Expandable rPET Green | C32: PN - 031 | D32: FSIN - 030 | E32: ASIN - 017 | G32: 19999 | H32: Check-in | I32: Green | J32: rPET | K32: Top-Open | L32: Yes
A33: Romulus | B33: Acer Romulus Suitcase 28 inch Check-in with 360 degree spin 8 Wheels TSA lock Top-Open Expandable rPET Pink | C33: PN - 032 | D33: FSIN - 031 | E33: ASIN - 018 | G33: 19999 | H33: Check-in | I33: Pink | J33: rPET | K33: Top-Open | L33: Yes
A34: Romulus | B34: Acer Romulus Overnighter Suitcase 19 inch Cabin with 360 degree spin 8 Wheels Double TSA lock Top-Open with Quick access compartment rPET White | C34: PN - 033 | D34: TBC | E34: TBC | F34: TBC | G34: 25999 | H34: Cabin | I34: White | J34: rPET | K34: Top-Open | L34: No
A35: Romulus | B35: Acer Romulus Suitcase 20 inch Cabin with 360 degree spin 8 Wheels TSA lock Top-Open Expandable with Quick access compartment rPET Azure Sky | C35: PN - 034 | D35: TBC | E35: TBC | F35: TBC | G35: 15999 | H35: Cabin | I35: Azure Sky | J35: rPET | K35: Top-Open | L35: Yes
A36: Evander | B36: Acer Evander Suitcase 20 inch Cabin with 360 degree spin 8 Wheels TSA lock Top Open Expandable rPET Mermaid Pink | C36: PN - 035 | D36: FSIN - 032 | E36: ASIN - 019 | G36: 16999 | H36: Cabin | I36: Mermaid Pink | J36: rPET | K36: Top-Open | L36: Yes
A37: Evander | B37: Acer Evander Suitcase 20 inch Cabin with 360 degree spin 8 Wheels TSA lock Top Open Expandable rPET Green | C37: PN - 036 | D37: FSIN - 033 | E37: ASIN - 020 | G37: 16999 | H37: Cabin | I37: Green | J37: rPET | K37: Top-Open | L37: Yes
A38: Evander | B38: Acer Evander Suitcase 20 inch Cabin with 360 degree spin 8 Wheels TSA lock Top Open Expandable rPET Gray | C38: PN - 037 | D38: FSIN - 034 | E38: ASIN - 021 | G38: 16999 | H38: Cabin | I38: Gray | J38: rPET | K38: Top-Open | L38: Yes
A39: Evander | B39: Acer Evander Suitcase 25 inch Check-in with 360 degree spin 8 Wheels Two TSA lock Top & Mid Open Expandable rPET Pink | C39: PN - 038 | D39: FSIN - 035 | E39: ASIN - 022 | G39: 18999 | H39: Check-in | I39: Pink | J39: rPET | K39: Dual Opening | L39: Yes
A40: Evander | B40: Acer Evander Suitcase 25 inch Check-in with 360 degree spin 8 Wheels Two TSA lock Top & Mid Open Expandable rPET Green | C40: PN - 039 | D40: FSIN - 036 | E40: ASIN - 023 | G40: 18999 | H40: Check-in | I40: Green | J40: rPET | K40: Dual Opening | L40: Yes
...

Sheet Weekly Insights
A1: Series | B1: Product | C1: Part Number | D1: FSN | E1: ASIN | F1: Myntra SKU Code | G1: Acer Stock | H1: Flipkart Stock | I1: Amazon Stock | J1: Myntra Stock | K1: Flipkart Sales Jul | L1: Flipkart Sales Jun | M1: Amazon Sales (Latest Report) | N1: Myntra Sales (Latest Report) | O1: Flipkart Sales (Till Date) | P1: Amazon Sales (Till Date) | Q1: Myntra Sales (Till Date) | R1: Total Inventory | S1: Total Sales Out
A2: Orion | B2: Orion 20" Cabin - Black | C2: PN - 001 | D2: FSIN - 001 | G2: 5 | H2: 11 | K2: 1 | L2: 5 | O2: 7 | R2: =SUM(G2,H2:J2) -> 16 | S2: =SUM(O2:Q2) -> 7
A3: Orion | B3: Orion 20" Cabin - White | C3: PN - 002 | D3: FSIN - 002 | G3: 7 | H3: 3 | L3: 6 | O3: 7 | R3: =SUM(G3,H3:J3) -> 10 | S3: =SUM(O3:Q3) -> 7
A4: Orion | B4: Orion 24" Check-in - Black | C4: PN - 003 | D4: FSIN - 003 | H4: 11 | K4: 1 | L4: 2 | O4: 5 | R4: =SUM(G4,H4:J4) -> 11 | S4: =SUM(O4:Q4) -> 5
A5: Orion | B5: Orion 24" Check-in - White | C5: PN - 004 | D5: FSIN - 004 | G5: 7 | H5: 8 | L5: 2 | O5: 3 | R5: =SUM(G5,H5:J5) -> 15 | S5: =SUM(O5:Q5) -> 3
A6: Aurelia | B6: Aurelia 19.5" Carry-on - Black | C6: PN - 005 | D6: FSIN - 005 | H6: 40 | O6: 0 | R6: =SUM(G6,H6:J6) -> 40 | S6: =SUM(O6:Q6) -> 0
A7: Aurelia | B7: Aurelia 19.5" Carry-on - White | C7: PN - 006 | D7: FSIN - 006 | G7: 1 | H7: 8 | L7: 1 | O7: 1 | R7: =SUM(G7,H7:J7) -> 9 | S7: =SUM(O7:Q7) -> 1
A8: Aurelia | B8: Aurelia 24" Check-in - Black | C8: PN - 007 | D8: FSIN - 007 | E8: ASIN - 001 | F8: SKU - 001 | G8: 5 | H8: 64 | I8: 14 | J8: 4 | M8: 1 | N8: 1 | O8: 1 | P8: 2 | Q8: 1 | R8: =SUM(G8,H8:J8) -> 87 | S8: =SUM(O8:Q8) -> 4
A9: Aurelia | B9: Aurelia 24" Check-in - White | C9: PN - 008 | D9: FSIN - 008 | E9: ASIN - 002 | F9: SKU - 002 | G9: 132 | H9: 43 | I9: 19 | J9: 1 | N9: 4 | O9: 0 | P9: 0 | Q9: 4 | R9: =SUM(G9,H9:J9) -> 195 | S9: =SUM(O9:Q9) -> 4
A10: Aurelia | B10: Aurelia 19.5+24+28" Set - Black | C10: PN - 009 | D10: FSIN - 009 | H10: 10 | O10: 0 | R10: =SUM(G10,H10:J10) -> 10 | S10: =SUM(O10:Q10) -> 0
A11: Aurelia | B11: Aurelia 19.5+24+28" Set - White | C11: PN - 010 | D11: FSIN - 010 | H11: 10 | O11: 0 | R11: =SUM(G11,H11:J11) -> 10 | S11: =SUM(O11:Q11) -> 0
A12: Cassian | B12: Cassian 20" Carry-on - Moreton Sand | C12: PN - 011 | D12: FSIN - 011 | E12: ASIN - 003 | F12: SKU - 003 | G12: 98 | H12: 43 | I12: 12 | J12: 4 | K12: 6 | L12: 3 | M12: 2 | N12: 1 | O12: 13 | P12: 2 | Q12: 1 | R12: =SUM(G12,H12:J12) -> 157 | S12: =SUM(O12:Q12) -> 16
A13: Cassian | B13: Cassian 20" Carry-on - Gold Coast | C13: PN - 012 | D13: FSIN - 012 | E13: ASIN - 004 | G13: 114 | H13: 23 | I13: 6 | O13: 0 | P13: 0 | R13: =SUM(G13,H13:J13) -> 143 | S13: =SUM(O13:Q13) -> 0
A14: Cassian | B14: Cassian 20" Carry-on - Jacaranda Pink | C14: PN - 013 | D14: FSIN - 013 | E14: ASIN - 005 | G14: 111 | H14: 23 | I14: 8 | M14: 1 | O14: 0 | P14: 1 | R14: =SUM(G14,H14:J14) -> 142 | S14: =SUM(O14:Q14) -> 1
A15: Cassian | B15: Cassian 24" Check-in - Moreton Sand | C15: PN - 014 | D15: FSIN - 014 | E15: ASIN - 006 | F15: SKU - 004 | G15: 163 | H15: 19 | I15: 34 | J15: 4 | K15: 6 | L15: 3 | M15: 5 | N15: 1 | O15: 12 | P15: 6 | Q15: 1 | R15: =SUM(G15,H15:J15) -> 220 | S15: =SUM(O15:Q15) -> 19
A16: Cassian | B16: Cassian 24" Check-in - Gold Coast | C16: PN - 015 | D16: FSIN - 015 | E16: ASIN - 007 | G16: 48 | H16: 30 | I16: 19 | O16: 0 | P16: 0 | R16: =SUM(G16,H16:J16) -> 97 | S16: =SUM(O16:Q16) -> 0
A17: Cassian | B17: Cassian 24" Check-in - Jacaranda Pink | C17: PN - 016 | D17: FSIN - 016 | E17: ASIN - 008 | G17: 254 | H17: 30 | I17: 19 | O17: 0 | P17: 0 | R17: =SUM(G17,H17:J17) -> 303 | S17: =SUM(O17:Q17) -> 0
A18: Cassian | B18: Cassian 28" Check-in - Moreton Sand | C18: PN - 017 | D18: FSIN - 017 | E18: ASIN - 009 | G18: 66 | H18: 29 | K18: 1 | M18: 1 | O18: 1 | P18: 3 | R18: =SUM(G18,H18:J18) -> 95 | S18: =SUM(O18:Q18) -> 4
A19: Cassian | B19: Cassian 28" Check-in - Jacaranda Pink | C19: PN - 018 | D19: FSIN - 018 | E19: ASIN - 010 | F19: SKU - 005 | G19: 54 | H19: 41 | I19: 24 | J19: 4 | K19: 7 | L19: 4 | M19: 1 | N19: 1 | O19: 11 | P19: 1 | Q19: 1 | R19: =SUM(G19,H19:J19) -> 123 | S19: =SUM(O19:Q19) -> 13
A20: Cassian | B20: Cassian 28" Check-in - Gold Coast | C20: PN - 019 | D20: TBC | E20: TBC | F20: TBC | G20: 100 | R20: =SUM(G20,H20:J20) -> 100 | S20: =SUM(O20:Q20) -> 0
A21: Romulus | B21: Romulus 19" Overnighter - Black | C21: PN - 020 | D21: FSIN - 019 | E21: ASIN - 011 | F21: SKU - 006 | G21: 3 | H21: 34 | I21: 61 | K21: 11 | L21: 2 | M21: 7 | N21: 3 | O21: 15 | P21: 10 | Q21: 3 | R21: =SUM(G21,H21:J21) -> 98 | S21: =SUM(O21:Q21) -> 28
A22: Romulus | B22: Romulus 19" Overnighter - Aqua Blue | C22: PN - 021 | D22: FSIN - 020 | E22: ASIN - 012 | F22: SKU - 007 | G22: 6 | H22: 32 | I22: 14 | J22: 1 | K22: 1 | N22: 1 | O22: 2 | P22: 0 | Q22: 1 | R22: =SUM(G22,H22:J22) -> 53 | S22: =SUM(O22:Q22) -> 3
A23: Romulus | B23: Romulus 19" Overnighter - Pink | C23: PN - 022 | D23: FSIN - 021 | E23: ASIN - 013 | G23: 4 | H23: 22 | I23: 10 | K23: 1 | M23: 2 | O23: 1 | P23: 2 | R23: =SUM(G23,H23:J23) -> 36 | S23: =SUM(O23:Q23) -> 3
A24: Romulus | B24: Romulus 20" Cabin - White | C24: PN - 023 | D24: FSIN - 022 | E24: ASIN - 014 | G24: 138 | H24: 26 | I24: 8 | O24: 0 | P24: 0 | R24: =SUM(G24,H24:J24) -> 172 | S24: =SUM(O24:Q24) -> 0
A25: Romulus | B25: Romulus 20" Cabin - Aqua Blue | C25: PN - 024 | D25: FSIN - 023 | H25: 6 | O25: 0 | R25: =SUM(G25,H25:J25) -> 6 | S25: =SUM(O25:Q25) -> 0
A26: Romulus | B26: Romulus 20" Cabin - Green | C26: PN - 025 | D26: FSIN - 024 | G26: 1 | H26: 4 | K26: 1 | L26: 1 | O26: 2 | R26: =SUM(G26,H26:J26) -> 5 | S26: =SUM(O26:Q26) -> 2
A27: Romulus | B27: Romulus 20" Cabin - Pink | C27: PN - 026 | D27: FSIN - 025 | G27: 85 | H27: 19 | O27: 1 | R27: =SUM(G27,H27:J27) -> 104 | S27: =SUM(O27:Q27) -> 1
A28: Romulus | B28: Romulus 25" Check-in - Black | C28: PN - 027 | D28: FSIN - 026 | E28: ASIN - 015 | G28: 253 | H28: 36 | I28: 11 | O28: 0 | P28: 0 | R28: =SUM(G28,H28:J28) -> 300 | S28: =SUM(O28:Q28) -> 0
A29: Romulus | B29: Romulus 25" Check-in - Green | C29: PN - 028 | D29: FSIN - 027 | G29: 185 | H29: 9 | O29: 0 | R29: =SUM(G29,H29:J29) -> 194 | S29: =SUM(O29:Q29) -> 0
A30: Romulus | B30: Romulus 25" Check-in - Pink | C30: PN - 029 | D30: FSIN - 028 | E30: ASIN - 016 | G30: 97 | H30: 30 | I30: 12 | O30: 0 | P30: 0 | R30: =SUM(G30,H30:J30) -> 139 | S30: =SUM(O30:Q30) -> 0
A31: Romulus | B31: Romulus 28" Check-in - Black | C31: PN - 030 | D31: FSIN - 029 | H31: 14 | K31: 1 | O31: 1 | R31: =SUM(G31,H31:J31) -> 14 | S31: =SUM(O31:Q31) -> 1
A32: Romulus | B32: Romulus 28" Check-in - Green | C32: PN - 031 | D32: FSIN - 030 | E32: ASIN - 017 | G32: 54 | H32: 23 | I32: 15 | L32: 1 | M32: 1 | O32: 1 | P32: 1 | R32: =SUM(G32,H32:J32) -> 92 | S32: =SUM(O32:Q32) -> 2
A33: Romulus | B33: Romulus 28" Check-in - Pink | C33: PN - 032 | D33: FSIN - 031 | E33: ASIN - 018 | G33: 209 | H33: 40 | I33: 38 | O33: 0 | P33: 1 | R33: =SUM(G33,H33:J33) -> 287 | S33: =SUM(O33:Q33) -> 1
A34: Romulus | B34: Romulus 19" Overnighter - White | C34: PN - 033 | D34: TBC | E34: TBC | F34: TBC | G34: 100 | R34: =SUM(G34,H34:J34) -> 100 | S34: =SUM(O34:Q34) -> 0
A35: Romulus | B35: Romulus 20" Cabin - Azure Sky | C35: PN - 034 | D35: TBC | E35: TBC | F35: TBC | G35: 100 | R35: =SUM(G35,H35:J35) -> 100 | S35: =SUM(O35:Q35) -> 0
A36: Evander | B36: Evander 20" Cabin - Mermaid Pink | C36: PN - 035 | D36: FSIN - 032 | E36: ASIN - 019 | G36: 18 | H36: 22 | I36: 5 | O36: 1 | P36: 0 | R36: =SUM(G36,H36:J36) -> 45 | S36: =SUM(O36:Q36) -> 1
A37: Evander | B37: Evander 20" Cabin - Green | C37: PN - 036 | D37: FSIN - 033 | E37: ASIN - 020 | G37: 73 | H37: 41 | I37: 6 | O37: 1 | P37: 0 | R37: =SUM(G37,H37:J37) -> 120 | S37: =SUM(O37:Q37) -> 1
A38: Evander | B38: Evander 20" Cabin - Gray | C38: PN - 037 | D38: FSIN - 034 | E38: ASIN - 021 | G38: 53 | H38: 27 | I38: 7 | K38: 1 | O38: 2 | P38: 0 | R38: =SUM(G38,H38:J38) -> 87 | S38: =SUM(O38:Q38) -> 2
A39: Evander | B39: Evander 25" Check-in - Pink | C39: PN - 038 | D39: FSIN - 035 | E39: ASIN - 022 | G39: 49 | H39: 28 | I39: 1 | L39: 2 | O39: 2 | P39: 0 | R39: =SUM(G39,H39:J39) -> 78 | S39: =SUM(O39:Q39) -> 2
A40: Evander | B40: Evander 25" Check-in - Green | C40: PN - 039 | D40: FSIN - 036 | E40: ASIN - 023 | G40: 10 | H40: 32 | I40: 2 | K40: 1 | L40: 1 | O40: 3 | P40: 0 | R40: =SUM(G40,H40:J40) -> 44 | S40: =SUM(O40:Q40) -> 3
...

Sheet Suitcase Series
A1: Series | B1: Acer Stock | C1: Total Sales Out | D1: Total Inventory | E1: Flipkart Sales | F1: Amazon Sales | G1: Myntra Sales | H1: Flipkart Stock | I1: Amazon Stock | J1: Myntra Stock | K1: Inventory Value @ MRP
A2: Orion | B2: =SUMIF(tblWeeklyInsights[Series],$A2,tblWeeklyInsights[Acer Stock]) -> 19 | C2: =SUM(E2:G2) -> 22 | D2: =SUM(B2,H2:J2) -> 52 | E2: =SUMIF(tblWeeklyInsights[Series],$A2,tblWeeklyInsights[Flipkart Sales (Till Date)]) -> 22 | F2: =SUMIF(tblWeeklyInsights[Series],$A2,tblWeeklyInsights[Amazon Sales (Till Date)]) -> 0 | G2: =SUMIF(tblWeeklyInsights[Series],$A2,tblWeeklyInsights[Myntra Sales (Till Date)]) -> 0 | H2: =SUMIF(tblWeeklyInsights[Series],$A2,tblWeeklyInsights[Flipkart Stock]) -> 33 | I2: =SUMIF(tblWeeklyInsights[Series],$A2,tblWeeklyInsights[Amazon Stock]) -> 0 | J2: =SUMIF(tblWeeklyInsights[Series],$A2,tblWeeklyInsights[Myntra Stock]) -> 0 | K2: {=SUMPRODUCT(('Product Master'!$A$2:$A$47=A2)*'Product Master'!$G$2:$G$47*_xlfn.XLOOKUP('Product Master'!$C$2:$C$47,'Weekly Insights'!$C$2:$C$46,'Weekly Insights'!$R$2:$R$46,0))} -> 805948
A3: Aurelia | B3: =SUMIF(tblWeeklyInsights[Series],$A3,tblWeeklyInsights[Acer Stock]) -> 138 | C3: =SUM(E3:G3) -> 9 | D3: =SUM(B3,H3:J3) -> 351 | E3: =SUMIF(tblWeeklyInsights[Series],$A3,tblWeeklyInsights[Flipkart Sales (Till Date)]) -> 2 | F3: =SUMIF(tblWeeklyInsights[Series],$A3,tblWeeklyInsights[Amazon Sales (Till Date)]) -> 2 | G3: =SUMIF(tblWeeklyInsights[Series],$A3,tblWeeklyInsights[Myntra Sales (Till Date)]) -> 5 | H3: =SUMIF(tblWeeklyInsights[Series],$A3,tblWeeklyInsights[Flipkart Stock]) -> 175 | I3: =SUMIF(tblWeeklyInsights[Series],$A3,tblWeeklyInsights[Amazon Stock]) -> 33 | J3: =SUMIF(tblWeeklyInsights[Series],$A3,tblWeeklyInsights[Myntra Stock]) -> 5 | K3: {=SUMPRODUCT(('Product Master'!$A$2:$A$47=A3)*'Product Master'!$G$2:$G$47*_xlfn.XLOOKUP('Product Master'!$C$2:$C$47,'Weekly Insights'!$C$2:$C$46,'Weekly Insights'!$R$2:$R$46,0))} -> 4964649
A4: Cassian | B4: =SUMIF(tblWeeklyInsights[Series],$A4,tblWeeklyInsights[Acer Stock]) -> 1008 | C4: =SUM(E4:G4) -> 53 | D4: =SUM(B4,H4:J4) -> 1380 | E4: =SUMIF(tblWeeklyInsights[Series],$A4,tblWeeklyInsights[Flipkart Sales (Till Date)]) -> 37 | F4: =SUMIF(tblWeeklyInsights[Series],$A4,tblWeeklyInsights[Amazon Sales (Till Date)]) -> 13 | G4: =SUMIF(tblWeeklyInsights[Series],$A4,tblWeeklyInsights[Myntra Sales (Till Date)]) -> 3 | H4: =SUMIF(tblWeeklyInsights[Series],$A4,tblWeeklyInsights[Flipkart Stock]) -> 238 | I4: =SUMIF(tblWeeklyInsights[Series],$A4,tblWeeklyInsights[Amazon Stock]) -> 122 | J4: =SUMIF(tblWeeklyInsights[Series],$A4,tblWeeklyInsights[Myntra Stock]) -> 12 | K4: {=SUMPRODUCT(('Product Master'!$A$2:$A$47=A4)*'Product Master'!$G$2:$G$47*_xlfn.XLOOKUP('Product Master'!$C$2:$C$47,'Weekly Insights'!$C$2:$C$46,'Weekly Insights'!$R$2:$R$46,0))} -> 24908620
A5: Romulus | B5: =SUMIF(tblWeeklyInsights[Series],$A5,tblWeeklyInsights[Acer Stock]) -> 1235 | C5: =SUM(E5:G5) -> 41 | D5: =SUM(B5,H5:J5) -> 1700 | E5: =SUMIF(tblWeeklyInsights[Series],$A5,tblWeeklyInsights[Flipkart Sales (Till Date)]) -> 23 | F5: =SUMIF(tblWeeklyInsights[Series],$A5,tblWeeklyInsights[Amazon Sales (Till Date)]) -> 14 | G5: =SUMIF(tblWeeklyInsights[Series],$A5,tblWeeklyInsights[Myntra Sales (Till Date)]) -> 4 | H5: =SUMIF(tblWeeklyInsights[Series],$A5,tblWeeklyInsights[Flipkart Stock]) -> 295 | I5: =SUMIF(tblWeeklyInsights[Series],$A5,tblWeeklyInsights[Amazon Stock]) -> 169 | J5: =SUMIF(tblWeeklyInsights[Series],$A5,tblWeeklyInsights[Myntra Stock]) -> 1 | K5: {=SUMPRODUCT(('Product Master'!$A$2:$A$47=A5)*'Product Master'!$G$2:$G$47*_xlfn.XLOOKUP('Product Master'!$C$2:$C$47,'Weekly Insights'!$C$2:$C$46,'Weekly Insights'!$R$2:$R$46,0))} -> 32906300
A6: Evander | B6: =SUMIF(tblWeeklyInsights[Series],$A6,tblWeeklyInsights[Acer Stock]) -> 352 | C6: =SUM(E6:G6) -> 13 | D6: =SUM(B6,H6:J6) -> 607 | E6: =SUMIF(tblWeeklyInsights[Series],$A6,tblWeeklyInsights[Flipkart Sales (Till Date)]) -> 12 | F6: =SUMIF(tblWeeklyInsights[Series],$A6,tblWeeklyInsights[Amazon Sales (Till Date)]) -> 1 | G6: =SUMIF(tblWeeklyInsights[Series],$A6,tblWeeklyInsights[Myntra Sales (Till Date)]) -> 0 | H6: =SUMIF(tblWeeklyInsights[Series],$A6,tblWeeklyInsights[Flipkart Stock]) -> 203 | I6: =SUMIF(tblWeeklyInsights[Series],$A6,tblWeeklyInsights[Amazon Stock]) -> 52 | J6: =SUMIF(tblWeeklyInsights[Series],$A6,tblWeeklyInsights[Myntra Stock]) -> 0 | K6: {=SUMPRODUCT(('Product Master'!$A$2:$A$47=A6)*'Product Master'!$G$2:$G$47*_xlfn.XLOOKUP('Product Master'!$C$2:$C$47,'Weekly Insights'!$C$2:$C$46,'Weekly Insights'!$R$2:$R$46,0))} -> 11469393
A7: Selene | B7: =SUMIF(tblWeeklyInsights[Series],$A7,tblWeeklyInsights[Acer Stock]) -> 193 | C7: =SUM(E7:G7) -> 8 | D7: =SUM(B7,H7:J7) -> 238 | E7: =SUMIF(tblWeeklyInsights[Series],$A7,tblWeeklyInsights[Flipkart Sales (Till Date)]) -> 8 | F7: =SUMIF(tblWeeklyInsights[Series],$A7,tblWeeklyInsights[Amazon Sales (Till Date)]) -> 0 | G7: =SUMIF(tblWeeklyInsights[Series],$A7,tblWeeklyInsights[Myntra Sales (Till Date)]) -> 0 | H7: =SUMIF(tblWeeklyInsights[Series],$A7,tblWeeklyInsights[Flipkart Stock]) -> 43 | I7: =SUMIF(tblWeeklyInsights[Series],$A7,tblWeeklyInsights[Amazon Stock]) -> 2 | J7: =SUMIF(tblWeeklyInsights[Series],$A7,tblWeeklyInsights[Myntra Stock]) -> 0 | K7: {=SUMPRODUCT(('Product Master'!$A$2:$A$47=A7)*'Product Master'!$G$2:$G$47*_xlfn.XLOOKUP('Product Master'!$C$2:$C$47,'Weekly Insights'!$C$2:$C$46,'Weekly Insights'!$R$2:$R$46,0))} -> 6553762

Sheet Pivot Tables
A1: Sales By Series | D1: Marketplace Sales | G1: Inventory Value By Series | J1: Sales Trend
A3: Row Labels | B3: Sales | D3: Marketplace | G3: Row Labels | H3: Inventory Value | J3: Month | K3: Flipkart Sales
A4: Cassian | B4: 53 | D4: Flipkart | E4: 104 | G4: Romulus | H4: 32906300 | J4: Jun | K4: 37
A5: Romulus | B5: 41 | D5: Amazon | E5: 30 | G5: Cassian | H5: 24908620 | J5: July | K5: 44
A6: Orion | B6: 22 | D6: Myntra | E6: 12 | G6: Evander | H6: 11469393 | J6: Grand Total | K6: =SUM(K4:K5) -> 81
A7: Evander | B7: 13 | D7: Grand Total | E7: =SUM(E4:E6) -> 146 | G7: Selene | H7: 6553762
A8: Aurelia | B8: 9 | G8: Aurelia | H8: 4964649
A9: Selene | B9: 8 | G9: Orion | H9: 805948
A10: Grand Total | B10: 146 | G10: Grand Total | H10: 81608672
A14: Inventory By Series | D14: Marketplace Stock | G14: Inventory Value By Location
A16: Row Labels | B16: Inventory | D16: Values | G16: Loction | H16: Inventory Value
A17: Romulus | B17: 1700 | D17: Flipkart | E17: 987 | G17: Acer | H17: {=SUMPRODUCT('Product Master'!G2:G47,_xlfn.XLOOKUP('Product Master'!C2:C47,'Weekly Insights'!C2:C46,'Weekly Insights'!G2:G46,0))} -> 55376055
A18: Cassian | B18: 1380 | D18: Amazon | E18: 378 | G18: Flipkart | H18: {=SUMPRODUCT('Product Master'!G2:G47,_xlfn.XLOOKUP('Product Master'!C2:C47,'Weekly Insights'!C2:C46,'Weekly Insights'!H2:H46,0))} -> 18455013
A19: Evander | B19: 607 | D19: Myntra | E19: 18 | G19: Amazon | H19: {=SUMPRODUCT('Product Master'!G2:G47,_xlfn.XLOOKUP('Product Master'!C2:C47,'Weekly Insights'!C2:C46,'Weekly Insights'!I2:I46,0))} -> 7466622
A20: Aurelia | B20: 351 | D20: Grand Total | E20: =SUM(E17:E19) -> 1383 | G20: Myntra | H20: {=SUMPRODUCT('Product Master'!G2:G47,_xlfn.XLOOKUP('Product Master'!C2:C47,'Weekly Insights'!C2:C46,'Weekly Insights'!J2:J46,0))} -> 310982
A21: Selene | B21: 238 | G21: Grand Total | H21: =SUM(H17:H20) -> 81608672
A22: Orion | B22: 52
A23: Grand Total | B23: 4328

Sheet README
A1: Marketplace Sales & Inventory Analytics Dashboard
A4: Project Overview
A5: This project analyzes sales performance and inventory distribution across multiple e-commerce marketplaces using Microsoft Excel. The dashboard provides an executive summary of inventory levels, product performance, and marketplace contribution through interactive visualizations, Pivot Tables, KPIs, and business insights.
A10: Project Objectives
A11: • Analyze sales performance across multiple product series.
A12: • Monitor inventory availability across marketplaces.
A13: • Compare marketplace sales and stock distribution.
A14: • Present executive KPIs through an interactive dashboard.
A15: • Support business decision-making through data visualization.
A17: Dashboard Components
A18: • Executive KPI Cards
A19: • Sales by Series Analysis
... A24: • Executive Dashboard
A26: Tools & Features Used | D26: Key Performance Indicators
A27: • Microsoft Excel | D27: • Total Sales
A28: • Excel Tables | D28: • Total Inventory
A30: • Structured References | D30: • Warehouse Stock
A31: • Pivot Tables | D31: • Active Marketplaces
A32: • Pivot Charts | D32: • Best Selling Series
A33: • SUM | D33: • Highest Inventory Series
A34: • INDEX
A35: • MATCH
A36: • Data Labels
A37: • Dashboard Design
A38: • Data Visualization
A39: • Business Analysis
A41: Skills Demonstrated | D41: Business Value
A42: • Data Cleaning | D42: • Enables quick sales monitoring.
A43: • Data Aggregation | D43: • Improves inventory visibility.
A44: • Dashboard Development | D44: • Identifies best-performing product series.
A45: • Data Visualization | D45: • Compares marketplace contribution.
A46: • Business Analytics | D46: • Supports data-driven business decisions.
A47: • Excel Reporting
A48: • Inventory Analysis
A49: • Sales Performance Analysis
A51: Future Enhancements
A52: • Power BI Dashboard Integration — Completed
A53: • Python Automation (Pandas & openpyxl)
A54: • Interactive Streamlit Dashboard
A55: • Automated Report Generation
...
